dnnlib: Running run_generator.generate_images() on localhost...
Il problema è il caricamento del decoder
Il problema è la scelta del device
Using device: cuda:0
Using device: cpu
Setting up TensorFlow plugin "fused_bias_act.cu": Preprocessing... Failed!
Traceback (most recent call last):
  File "run_generator.py", line 227, in <module>
    main()
  File "run_generator.py", line 222, in main
    dnnlib.submit_run(sc, func_name_map[subcmd], **kwargs)
  File "/home/giacomo/Desktop/codice 19-08/stylegan2_mio/dnnlib/submission/submit.py", line 343, in submit_run
    return farm.submit(submit_config, host_run_dir)
  File "/home/giacomo/Desktop/codice 19-08/stylegan2_mio/dnnlib/submission/internal/local.py", line 22, in submit
    return run_wrapper(submit_config)
  File "/home/giacomo/Desktop/codice 19-08/stylegan2_mio/dnnlib/submission/submit.py", line 280, in run_wrapper
    run_func_obj(**submit_config.run_func_kwargs)
  File "/home/giacomo/Desktop/codice 19-08/stylegan2_mio/run_generator.py", line 47, in generate_images
    state_dict = torch.load(decoder_path, map_location=device)
  File "/home/giacomo/.pyenv/versions/stylegan2/lib/python3.7/site-packages/torch/serialization.py", line 795, in load
    return _legacy_load(opened_file, map_location, pickle_module, **pickle_load_args)
  File "/home/giacomo/.pyenv/versions/stylegan2/lib/python3.7/site-packages/torch/serialization.py", line 1002, in _legacy_load
    magic_number = pickle_module.load(f, **pickle_load_args)
  File "/home/giacomo/Desktop/codice 19-08/stylegan2_mio/dnnlib/tflib/network.py", line 297, in __setstate__
    self._init_graph()
  File "/home/giacomo/Desktop/codice 19-08/stylegan2_mio/dnnlib/tflib/network.py", line 154, in _init_graph
    out_expr = self._build_func(*self.input_templates, **build_kwargs)
  File "<string>", line 491, in G_synthesis_stylegan2
  File "<string>", line 455, in layer
  File "<string>", line 99, in modulated_conv2d_layer
  File "<string>", line 68, in apply_bias_act
  File "/home/giacomo/Desktop/codice 19-08/stylegan2_mio/dnnlib/tflib/ops/fused_bias_act.py", line 68, in fused_bias_act
    return impl_dict[impl](x=x, b=b, axis=axis, act=act, alpha=alpha, gain=gain)
  File "/home/giacomo/Desktop/codice 19-08/stylegan2_mio/dnnlib/tflib/ops/fused_bias_act.py", line 122, in _fused_bias_act_cuda
    cuda_kernel = _get_plugin().fused_bias_act
  File "/home/giacomo/Desktop/codice 19-08/stylegan2_mio/dnnlib/tflib/ops/fused_bias_act.py", line 16, in _get_plugin
    return custom_ops.get_plugin(os.path.splitext(__file__)[0] + '.cu')
  File "/home/giacomo/Desktop/codice 19-08/stylegan2_mio/dnnlib/tflib/custom_ops.py", line 130, in get_plugin
    compile_opts += ' --gpu-architecture=%s' % _get_cuda_gpu_arch_string()
  File "/home/giacomo/Desktop/codice 19-08/stylegan2_mio/dnnlib/tflib/custom_ops.py", line 52, in _get_cuda_gpu_arch_string
    raise RuntimeError('No GPU devices found')
RuntimeError: No GPU devices found
